ERROR:root:Foo.bar1
  raised Exception: BAR1!
    called with args = ("<class '__main__.Foo'>",), kwargs = {}
    at 2022-03-07 23:58:09.763220-05:00
Traceback (most recent call last):
  File "/home/ryan/exception-logging-decorator/src/exlog/exceptlog.py", line 58, in wrapper
    output = function(*args, **kwargs)
  File "./tests/test_cls.py", line 21, in bar1
    raise Exception("BAR1!")
Exception: BAR1!
ERROR:root:Foo.bar2
  raised Exception: BAR2!
    called with args = (), kwargs = {}
    at 2022-03-07 23:58:09.763678-05:00
Traceback (most recent call last):
  File "/home/ryan/exception-logging-decorator/src/exlog/exceptlog.py", line 58, in wrapper
    output = function(*args, **kwargs)
  File "./tests/test_cls.py", line 24, in bar2
    raise Exception("BAR2!")
Exception: BAR2!
ERROR:root:Foo.bar3
  raised Exception: BAR3!
    called with args = ('<__main__.Foo object at 0x7fefc0bb5a90>',), kwargs = {}
    at 2022-03-07 23:58:09.763792-05:00
Traceback (most recent call last):
  File "/home/ryan/exception-logging-decorator/src/exlog/exceptlog.py", line 58, in wrapper
    output = function(*args, **kwargs)
  File "./tests/test_cls.py", line 26, in bar3
    raise Exception("BAR3!")
Exception: BAR3!
