ERROR:root:Foo.bar1
  raised Exception: BAR1!
    called with args = ("<class '__main__.Foo'>",), kwargs = {}
    at 2022-03-08 14:02:44.949408-05:00
Traceback (most recent call last):
  File "/home/ryan/exception-logging/src/exlog/exceptlog.py", line 58, in wrapper
    output = function(*args, **kwargs)
  File "/home/ryan/exception-logging/./tests/test_cls.py", line 21, in bar1
    raise Exception("BAR1!")
Exception: BAR1!
ERROR:root:Foo.bar2
  raised TypeError: Foo.bar2() takes 0 positional arguments but 1 was given
    called with args = ('<__main__.Foo object at 0x7fed4b605d20>',), kwargs = {}
    at 2022-03-08 14:02:44.949832-05:00
Traceback (most recent call last):
  File "/home/ryan/exception-logging/src/exlog/exceptlog.py", line 58, in wrapper
    output = function(*args, **kwargs)
TypeError: Foo.bar2() takes 0 positional arguments but 1 was given
ERROR:root:Foo.bar3
  raised Exception: BAR3!
    called with args = ('<__main__.Foo object at 0x7fed4b605d20>',), kwargs = {}
    at 2022-03-08 14:02:44.949943-05:00
Traceback (most recent call last):
  File "/home/ryan/exception-logging/src/exlog/exceptlog.py", line 58, in wrapper
    output = function(*args, **kwargs)
  File "/home/ryan/exception-logging/./tests/test_cls.py", line 26, in bar3
    raise Exception("BAR3!")
Exception: BAR3!
