ERROR:root:Foo.bar1
  raised Exception: BAR1!
    called with args = ('<__main__.Foo object at 0x7fa03d60c820>',), kwargs = {}
    at 2022-03-07 23:56:52.007691-05:00
Traceback (most recent call last):
  File "/home/ryan/exception-logging-decorator/src/exlog/exceptlog.py", line 58, in wrapper
    output = function(*args, **kwargs)
  File "./tests/test_cls.py", line 21, in bar1
    raise Exception("BAR1!")
Exception: BAR1!
ERROR:root:Foo.bar2
  raised TypeError: bar2() takes 0 positional arguments but 1 was given
    called with args = ('<__main__.Foo object at 0x7fa03d60c820>',), kwargs = {}
    at 2022-03-07 23:56:52.008251-05:00
Traceback (most recent call last):
  File "/home/ryan/exception-logging-decorator/src/exlog/exceptlog.py", line 58, in wrapper
    output = function(*args, **kwargs)
TypeError: bar2() takes 0 positional arguments but 1 was given
ERROR:root:Foo.bar3
  raised Exception: BAR3!
    called with args = ('<__main__.Foo object at 0x7fa03d60c820>',), kwargs = {}
    at 2022-03-07 23:56:52.008365-05:00
Traceback (most recent call last):
  File "/home/ryan/exception-logging-decorator/src/exlog/exceptlog.py", line 58, in wrapper
    output = function(*args, **kwargs)
  File "./tests/test_cls.py", line 26, in bar3
    raise Exception("BAR3!")
Exception: BAR3!
