ERROR:root:Foo.bar1
  raised Exception: METABAR1!
    called with args = ('<__main__.Foo object at 0x7fbe72906eb0>',), kwargs = {}
    at 2022-03-07 23:35:13.729253-05:00
Traceback (most recent call last):
  File "/home/ryan/exception-logging-decorator/src/exlog/exceptlog.py", line 58, in wrapper
    output = function(*args, **kwargs)
  File "./tests/test_meta.py", line 26, in bar1
    raise Exception("METABAR1!")
Exception: METABAR1!
ERROR:root:Foo.bar2
  raised TypeError: bar2() takes 0 positional arguments but 1 was given
    called with args = ('<__main__.Foo object at 0x7fbe72906eb0>',), kwargs = {}
    at 2022-03-07 23:35:13.730106-05:00
Traceback (most recent call last):
  File "/home/ryan/exception-logging-decorator/src/exlog/exceptlog.py", line 58, in wrapper
    output = function(*args, **kwargs)
TypeError: bar2() takes 0 positional arguments but 1 was given
ERROR:root:Foo.bar3
  raised Exception: METABAR3!
    called with args = ('<__main__.Foo object at 0x7fbe72906eb0>',), kwargs = {}
    at 2022-03-07 23:35:13.730221-05:00
Traceback (most recent call last):
  File "/home/ryan/exception-logging-decorator/src/exlog/exceptlog.py", line 58, in wrapper
    output = function(*args, **kwargs)
  File "./tests/test_meta.py", line 31, in bar3
    raise Exception("METABAR3!")
Exception: METABAR3!
